Workbook

Sheet Rambudget
C1: Konglig Datasektionen Budget 2025
D2: Budget 2025 | I2: Kommentarer
A4: Flikindex | B4: Resultatställe | C4: Intäkter | D4: Utgifter | E4: Resultat
B6: Nämnder
A7: 1 | B7: Ada | C7: ='1 - Ada'!E40 -> 15200 | D7: ='1 - Ada'!F40 -> -23380 | E7: ='1 - Ada'!G40 -> -8180 | I7: Event ökad och uppdelad, sittningar standardiserade
A8: 3 | B8: Datasladden | C8: ='3 - Datasladden'!E25 -> 0 | D8: ='3 - Datasladden'!F25 -> -120300 | E8: ='3 - Datasladden'!G25 -> -120300 | I8: Luskostnader verklighetsjusterade
A9: 4 | B9: D-Dagen | C9: ='4 - D-Dagen'!E92 -> 4273890 | D9: ='4 - D-Dagen'!F92 -> -1968910 | E9: ='4 - D-Dagen'!G92 -> 2304980 | I9: Småfix, Max Berglund löser resten till Glögg-SM
A10: 5 | B10: DEMON | C10: ='5 - DEMON'!E9 -> 0 | D10: ='5 - DEMON'!F9 -> -26500 | E10: ='5 - DEMON'!G9 -> -26500 | I10: Oförändrad från 2024, Eynar Ason Eklöfs motion & motionssvar löser
A11: 6 | B11: DESC | C11: ='6 - DESC'!E31 -> 2000 | D11: ='6 - DESC'!F31 -> -30750 | E11: ='6 - DESC'!G31 -> -28750 | I11: LAN-Event budget förbättrad, Allmänt konsoliderad
A12: 7 | B12: D-Festeriet | C12: ='7 - D-Festeriet'!E113 -> 122735 | D12: ='7 - D-Festeriet'!F113 -> -130934 | E12: ='7 - D-Festeriet'!G113 -> -8199 | I12: dFunkteambuilding återvandrad, sittningsstandardisering
A13: 8 | B13: dJulkalendern | C13: ='8 - dJulkalendern'!E18 -> 870 | D13: ='8 - dJulkalendern'!F18 -> -11540 | E13: ='8 - dJulkalendern'!G18 -> -10670 | I13: Typ oförändrad, Jonathan Almgren s motion & motionssvar löser
A14: 9 | B14: DKM | C14: ='9 - DKM'!E141 -> 752290 | D14: ='9 - DKM'!F141 -> -814806 | E14: ='9 - DKM'!G141 -> -62516 | I14: Flera justeringar, se detaljbudget
A15: 11 | B15: D-Rektoratet | C15: ='204 - D-Rektoratet'!E43 -> 6100 | D15: ='204 - D-Rektoratet'!F43 -> -125500 | E15: ='204 - D-Rektoratet'!G43 -> -119400 | I15: Alumnpraxis D-wreck. Städning av Allmänt
A16: 12 | B16: GUDAR | C16: ='11 - GUDAR'!E19 -> 0 | D16: ='11 - GUDAR'!F19 -> -4983 | E16: ='11 - GUDAR'!G19 -> -4983 | I16: Retro & 1983 dog
A17: 13 | B17: Idrottsnämnden | C17: ='12 - Idrottsnämnden'!E12 -> 30000 | D17: ='12 - Idrottsnämnden'!F12 -> -87000 | E17: ='12 - Idrottsnämnden'!G12 -> -57000 | I17: Gruppering av event & Tech-i-taka långsiktighet
A18: 14 | B18: IOR | C18: ='13 - IOR'!E17 -> 0 | D18: ='13 - IOR'!F17 -> -69500 | E18: ='13 - IOR'!G17 -> -69500 | I18: Fix TB och uppdelning av gigaposten
A19: 15 | B19: IN | C19: ='14 - IN'!E82 -> 47860 | D19: ='14 - IN'!F82 -> -80304 | E19: ='14 - IN'!G82 -> -32444 | I19: Split Event, 4 Gasques instead of 2, standardized
A20: 16 | B20: JN | C20: ='15 - JN'!E20 -> 0 | D20: ='15 - JN'!F20 -> -13200 | E20: ='15 - JN'!G20 -> -13200 | I20: Split event, profilkläder bort
A21: 28 | B21: Kommunikationsgruppen | C21: ='16 - Kommunikationsgruppen'!E10 -> 0 | D21: ='16 - Kommunikationsgruppen'!F10 -> -1600 | E21: ='16 - Kommunikationsgruppen'!G10 -> -1600
A22: 17 | B22: MKM | C22: ='17 - MKM'!E55 -> 478750 | D22: ='17 - MKM'!F55 -> -478750 | E22: ='17 - MKM'!G55 -> 0 | I22: Mottagningsgasque split & verklighetsjustering Verksamhet
A23: 18 | B23: Mottagningen | C23: ='18 - Mottagningen'!E528 -> 557600 | D23: ='18 - Mottagningen'!F528 -> -1359920 | E23: ='18 - Mottagningen'!G528 -> -802320 | I23: Tom, motion & motionssvar löser
A24: 19 | B24: NLG | C24: ='19 - NLG'!E51 -> 528000 | D24: ='19 - NLG'!F51 -> -224450 | E24: ='19 - NLG'!G51 -> 303550 | I24: Prissänkning företagspub, småsaker
A25: 20 | B25: Prylmångleriet | C25: ='20 - Prylmångleriet'!E22 -> 361000 | D25: ='20 - Prylmångleriet'!F22 -> -351200 | E25: ='20 - Prylmångleriet'!G22 -> 9800
A26: 21 | B26: QN | C26: ='21 - QN'!E10 -> 0 | D26: ='21 - QN'!F10 -> -19000 | E26: ='21 - QN'!G10 -> -19000
A27: 22 | B27: Redaqtionen | C27: ='22 - Redaqtionen'!E18 -> 6500 | D27: ='22 - Redaqtionen'!F18 -> -24000 | E27: ='22 - Redaqtionen'!G18 -> -17500
A28: 24 | B28: SLG | C28: ='24 - SLG'!E62 -> 54160 | D28: ='24 - SLG'!F62 -> -188444 | E28: ='24 - SLG'!G62 -> -134284
A29: 25 | B29: Studienämnden | C29: ='25 - Studienämnden'!E19 -> 8400 | D29: ='25 - Studienämnden'!F19 -> -48200 | E29: ='25 - Studienämnden'!G19 -> -39800
A30: 27 | B30: Valberedningen | C30: ='205 - Valberedningen'!E26 -> 0 | D30: ='205 - Valberedningen'!F26 -> -13050 | E30: ='205 - Valberedningen'!G26 -> -13050
A31: 104 | B31: Dive | C31: ='26 - Dive'!E20 -> 6000 | D31: ='26 - Dive'!F20 -> -27000 | E31: ='26 - Dive'!G20 -> -21000
B33: Total Nämnder | C33: =SUM(C7:C31) -> 7251355 | D33: =SUM(D7:D31) -> -6243221 | E33: =SUM(E7:E31) -> 1008134
B35: Projekt
A36: 103 | B36: Studs 2025 | C36: ='103 - Studs 2025'!E49 -> 807300 | D36: ='103 - Studs 2025'!F49 -> -800960 | E36: ='103 - Studs 2025'!G49 -> 6340
B37: METAspexet 2026 | C37: ='109 - METAspexet 2026'!E139 -> 306400 | D37: ='109 - METAspexet 2026'!F139 -> -373970 | E37: ='109 - METAspexet 2026'!G139 -> -67570
B38: Datas DansRevolution | C38: ='Datas DansRevolution'!E8 -> 0 | D38: ='Datas DansRevolution'!F8 -> -750 | E38: ='Datas DansRevolution'!G8 -> -750
B39: Vårbalen 2026 | C39: ='Vårbalen 2026'!E42 -> 121270 | D39: ='Vårbalen 2026'!F42 -> -198721 | E39: ='Vårbalen 2026'!G42 -> -77451
B41: Total Projekt | C41: =SUM(C36:C38) -> 1113700 | D41: =SUM(D36:D38) -> -1175680 | E41: =SUM(E36:E38) -> -61980
B43: Övrigt
A44: 201 | B44: Centralt | C44: ='201 - Centralt'!E35 -> 274000 | D44: ='201 - Centralt'!F35 -> -356350 | E44: ='201 - Centralt'!G35 -> -82350
A45: 202 | B45: Beslutspengar - Engångskostnader | C45: ='202 - Beslutspengar - Engångsko'!E24 -> 0 | D45: ='202 - Beslutspengar - Engångsko'!F24 -> -136650 | E45: ='202 - Beslutspengar - Engångsko'!G24 -> -136650
A46: 203 | B46: dFunk | C46: ='203 - dFunk'!E27 -> 0 | D46: ='203 - dFunk'!F27 -> -51000 | E46: ='203 - dFunk'!G27 -> -48000
...

Sheet 1 - Ada
A1: Resultatställe | B1: Sekundärtresultatställe | C1: Budgetpost | D1: Konto | E1: Intäkter | F1: Utgifter | G1: Balans | H1: Kommentarer
A2: Ada
A3: Nämnd | B3: Allmänt
C4: Eventfika | D4: 4045 | E4: 0 | F4: -2000
C5: Pyssel | D5: 5411 | E5: 0 | F5: -2000
C7: Subsubtotal | E7: =SUM(E4:E5) -> 0 | F7: =SUM(F4:F5) -> -4000 | G7: =E7+F7 -> -4000
B9: Internt
C10: Teambuilding | D10: 7631 | E10: 0 | F10: -3000
C11: Fika | D11: 7691 | E11: 0 | F11: -900
C12: Försäljning profilkläder | D12: 3044 | E12: 900 | F12: 0
C13: Inköp profilkläder | D13: 4044 | E13: 0 | F13: -1800
C15: Subsubtotal | E15: =SUM(E10:E13) -> 900 | F15: =SUM(F10:F13) -> -5700 | G15: =E15+F15 -> -4800
B17: Vårsittning | H17: Standardiserad
C18: Biljetter | D18: 3041, 3042 | E18: 7150 | F18: 0 | H18: 190 Alk, 145 Alkfri
C19: Sittningsdryck | D19: 3021-3025 | E19: 0 | F19: -1640 | H19: Räknat på 40 pers, 25% alkfri
C20: Mat | D20: 4029 | E20: 0 | F20: -2400 | H20: 60kr per person
C21: Dekoration | D21: 5411 | E21: 0 | F21: -800
C22: Personalvård | D22: 7691 | E22: 0 | F22: -200
C23: Engångsartiklar | D23: 5463 | E23: 0 | F23: -400
C24: Märken | D24: 4027 | E24: 0 | F24: -1400
C26: Subsubtotal | E26: =SUM(E18:E24) -> 7150 | F26: =SUM(F18:F24) -> -6840 | G26: =E26+F26 -> 310
B28: Höstsittning | H28: Standardiserad
C29: Biljetter | D29: 3041, 3042 | E29: 7150 | F29: 0 | H29: 190 Alk, 145 Alkfri
C30: Sittningsdryck | D30: 3021-3025 | E30: 0 | F30: -1640 | H30: Räknat på 40 pers, 25% alkfri
C31: Mat | D31: 4029 | E31: 0 | F31: -2400 | H31: 60kr per person
C32: Kökshyra | D32: 5010 | E32: 0 | F32: -600
C33: Dekoration | D33: 5411 | E33: 0 | F33: -500
C34: Personalvård | D34: 7691 | E34: 0 | F34: -200
C35: Engångsartiklar | D35: 5463 | E35: 0 | F35: -400
C36: Märken | D36: 4027 | E36: 0 | F36: -1100
C38: Subsubtotal | E38: =SUM(E29:E36) -> 7150 | F38: =SUM(F29:F36) -> -6840 | G38: =E38+F38 -> 310
C40: Subtotal | E40: =SUMIFS(E2:E39,$C2:$C39,"Subsubtotal") -> 15200 | F40: =SUMIFS(F2:F39,$C2:$C39,"Subsubtotal") -> -23380 | G40: =SUM(G2:G39) -> -8180

Sheet 3 - Datasladden
A1: Resultatställe | B1: Sekundärtresultatställe | C1: Budgetpost | D1: Konto | E1: Intäkter | F1: Utgifter | G1: Balans | H1: Kommentarer
A2: Datasladden
A3: Nämnd | B3: Allmänt
C4: Godis | D4: 4045 | E4: 0 | F4: -3000
C5: Kraschmedaljer | D5: 7630 | E5: 0 | F5: -1000
C6: Tillbehör | D6: 4030 | E6: 0 | F6: -1500
C8: Subsubtotal | E8: =SUM(E4:E6) -> 0 | F8: =SUM(F4:F6) -> -5500 | G8: =E8+F8 -> -5500
B10: Internt
C11: Teambuilding | D11: 7631 | E11: 0 | F11: -1750
C12: Fika | D12: 7691 | E12: 0 | F12: -1050
C14: Subsubtotal | E14: =SUM(E11:E12) -> 0 | F14: =SUM(F11:F12) -> -2800 | G14: =E14+F14 -> -2800
B16: Bil
C17: Drivmedel | D17: 5611 | E17: 0 | F17: -35000
C18: Skatt & Försäkring | D18: 5612 | E18: 0 | F18: -18000 | H18: 14k försäkring, 4k fordonsskatt | I18: Sammanslagen, samma bokföringskonto + ingen bryr sig
C19: Trängselskatt | D19: 5616 | E19: 0 | F19: -4000 | H19: Skurubron & trängselskatt | I19: Splittad från skatter
C20: Parkering | D20: 5617 | E20: 0 | F20: -25000 | H20: 21k Campus, resten ströparkeringar
C21: Underhåll av bil | D21: 5613 | E21: 0 | F21: -30000
C23: Subsubtotal | E23: =SUM(E17:E21) -> 0 | F23: =SUM(F17:F21) -> -112000 | G23: =E23+F23 -> -112000
C25: Subtotal | E25: =SUMIFS(E2:E23,$C2:$C23,"Subsubtotal") -> 0 | F25: =SUMIFS(F2:F23,$C2:$C23,"Subsubtotal") -> -120300 | G25: =E25+F25 -> -120300

Sheet 4 - D-Dagen
A1: Resultatställe | B1: Sekundärtresultatställe | C1: Budgetpost | D1: Konto | E1: Intäkter | F1: Utgifter | G1: Balans | H1: Kommentarer
A2: D-Dagen
A3: Nämnd | B3: Allmänt
C4: Arbetskläder - Flugor+näsdukar | E4: 0 | F4: -15000 | H4: Med 15% rabatt
C5: Arbetskläder - Tröjor | E5: 0 | F5: -25000
C6: Teambuilding - Personal | D6: 7631 | E6: 0 | F6: -30090 | H6: 170kr/person (150st dagspersonal och 27st Projektgrupp)
C7: Lunchföreläsningar | E7: 111000 | F7: 0 | H7: 37 000kr/lunchföreläsning
C8: Mat för lunchföreläsningar | E8: 0 | F8: -52000 | H8: 13 000kr/lunchföreläsning, räknat 4st med Huvudspons
C9: After Works Extern | E9: 17000 | F9: 0 | H9: After Works för studenter
C11: Subsubtotal | E11: =SUM(E4:E9) -> 128000 | F11: =SUM(F4:F9) -> -122090 | G11: =E11+F11 -> 5910
B13: Internt
C14: Fika | D14: 7691 | E14: 0 | F14: -16200 | H14: 600kr/person
C15: Mat - Stormöten | D15: 7692 | E15: 0 | F15: -14040 | H15: 130kr/person/möte (27st personer och 4st möten)
C16: Medaljer | D16: 7630 | E16: 0 | F16: -3500
C17: Profilkläder | D17: 5931 | E17: 0 | F17: -27000 | H17: 1 000kr/person
C18: Representation & inspiration | D18: 5800 | E18: 0 | F18: -6000 | H18: Besöka andra mässor (Göteborg, Lund, Linköping, Luleå). 1000kr/person/resa. 3st olika resor.
C19: Alumnevent | D19: 7692 | E19: 0 | F19: -2500
C20: Teambuilding - Projektgrupp | D20: 7631 | E20: 0 | F20: -27000 | H20: 1 000kr/person
C21: Licenser | D21: 5420 | E21: 0 | F21: -4620 | H21: Adobe
C23: Subsubtotal | E23: =SUM(E14:E21) -> 0 | F23: =SUM(F14:F21) -> -100860 | G23: =E23+F23 -> -100860
B25: Mässan
C26: Huvudsponsor | E26: 160000 | F26: 0
C27: Lilla paketet | E27: 2520000 | F27: 0 | H27: 35 000kr/paket (72st)
C28: Mellanpaketet | E28: 940000 | F28: 0 | H28: 47 000kr/paket (20st)
C29: Stora paketet | E29: 354000 | F29: 0 | H29: 59 000kr/paket (6st)
C30: Startup-paketet | E30: 30000 | F30: 0 | H30: 10 000kr/paket (3st)
C31: Extra beställningar | E31: 75000 | F31: 0
C32: Lokalhyra | E32: 0 | F32: -360500 | H32: 312 500kr för Nymble och 38 000kr Kårbokhandeln. Detta är priser vi fick från dem 2024, vi förväntar oss prishöjning 2025.
C33: Inhyrt material | E33: 0 | F33: -32000
C34: Hyrbil | E34: 0 | F34: -4000
C35: Sophantering | E35: 0 | F35: -1000
C36: Dekoration | E36: 0 | F36: -112000
C37: Marknadsföring - Tryck | E37: 0 | F37: -152000
C38: Marknadsföring - Fika | E38: 0 | F38: -4000
C39: Marknadsföring - Digital | E39: 0 | F39: -30000
C40: Goodiebags | E40: 0 | F40: -100000 | H40: 68kr/påse
C41: Catering | E41: 0 | F41: -160800 | H41: 218kr/person för frukost och lunch för 600 personer. Sedan kaffe och fika för företag.
C42: Personalvård | E42: 0 | F42: -26250 | H42: För Preppdagen, Mässdagen och Slasquedagen
C43: Brandutbildning | E43: 0 | F43: -3500
C45: Subsubtotal | E45: =SUM(E26:E43) -> 4079000 | F45: =SUM(F26:F43) -> -986050 | G45: =E45+F45 -> 3092950
...

Sheet 5 - DEMON
A1: Resultatställe | B1: Sekundärtresultatställe | C1: Budgetpost | D1: Konto | E1: Intäkter | F1: Utgifter | G1: Balans | H1: Kommentarer
A2: DEMON
A3: Nämnd | B3: Allmänt
C4: Repfika | D4: 7691 | E4: 0 | F4: -150
C5: Replokal | D5: 5010 | E5: 0 | F5: =-(25000+1350) -> -26350
C7: Subsubtotal | E7: =SUM(E4:E6) -> 0 | F7: =SUM(F4:F6) -> -26500 | G7: =E7+F7 -> -26500
C9: Subtotal | E9: =SUMIFS(E2:E8,$C2:$C8,"Subsubtotal") -> 0 | F9: =SUMIFS(F2:F8,$C2:$C8,"Subsubtotal") -> -26500 | G9: =SUM(G2:G8) -> -26500

Sheet 6 - DESC
A1: Resultatställe | B1: Sekundärtresultatställe | C1: Budgetpost | D1: Konto | E1: Intäkter | F1: Utgifter | G1: Balans | H1: Kommentarer
A2: DESC
A3: Nämnd | B3: Allmänt
C4: Spel & Speltillbehör | D4: 4030 | E4: 0 | F4: -5000 | I4: Sammanslagen
C6: Subsubtotal | E6: =SUM(E4:E5) -> 0 | F6: =SUM(F4:F5) -> -5000 | G6: =E6+F6 -> -5000
B8: Internt
C9: Fika | E9: 0 | F9: -750
C11: Subsubtotal | E11: =SUM(E9) -> 0 | F11: =SUM(F9) -> -750 | G11: =SUM(E11:F11) -> -750
B13: Event | I13: BIG justering pga. minussumman borde tas ur TB
C14: Priser | D14: 7630 | E14: 0 | F14: -1500 | H14: Symboliska priser
C15: Lokalhyra | D15: 5010 | E15: 0 | F15: -7500 | I15: 1 dag i Nya Matsalen, höftat. För en hel CCLAN kanske vi tar med någon till sektion som kan dela på kostnaderna
C16: Tryck | D16: 6150 | E16: 0 | F16: -500
C17: Snacks | D17: 4045 | E17: 0 | F17: -2000 | H17: Sånt som inte ersätter måltid
C18: Försäljning mat | D18: 3029 | E18: 2000 | F18: 0 | H18: Sånt som ersätter måltid
C19: Inköp mat | D19: 4029 | E19: 0 | F19: -2000 | H19: Sånt som ersätter måltid
C21: Subsubtotal | E21: =SUM(E14:E19) -> 2000 | F21: =SUM(F14:F19) -> -13500 | G21: =E21+F21 -> -11500
B23: METAcraft | I23: Oförändrad pga glömde fråga :skull:
C24: Hosting | D24: 6541 | E24: 0 | F24: -8000
C25: Fika | D25: 7691 | E25: 0 | F25: -750
C26: Eventfika | D26: 4045 | E26: 0 | F26: -1500 | I26: Bytt namn från event
C27: Teambuilding | D27: 7631 | E27: 0 | F27: -1250
C29: Subsubtotal | E29: =SUM(E24:E27) -> 0 | F29: =SUM(F24:F27) -> -11500 | G29: =E29+F29 -> -11500
C31: Subtotal | E31: =SUMIFS(E2:E30,$C2:$C30,"Subsubtotal") -> 2000 | F31: =SUMIFS(F2:F30,$C2:$C30,"Subsubtotal") -> -30750 | G31: =SUM(G2:G30) -> -28750

Sheet 7 - D-Festeriet
A1: Resultatställe | B1: Sekundärtresultatställe | C1: Budgetpost | D1: Konto | E1: Intäkter | F1: Utgifter | G1: Balans | H1: Kommentarer
A2: D-Festeriet
A3: Nämnd | B3: EECS-Gasquen
C4: EECS-Bidrag andra sektioner | D4: 3989 | E4: 9000 | F4: 0 kr | J4: EECS-bidrag från andra sektioner (vi fakturerar)
C5: Biljetter | D5: 3041, 3042 | E5: 44000 | F5: 0 kr | I5: Höjd 4k för Ø-budget | J5: 200 x 200 = 40000, ser väldigt möjligt ut att sänka biljettkostnad
C6: Dekoration | D6: 5411 | E6: 0 kr | F6: -3000 | J6: Går potentiellt att få ner, vi bollar vissa idéer
C7: Engångsartiklar | D7: 5463 | E7: 0 kr | F7: -1500
C8: Lokalhyra | D8: 5010 | E8: 0 kr | F8: -7700 | J8: 9500 kr hyra för nya matsalen + hyllan per THS. 2 kök x 2 pass + 2 x 1 pass. 200kr per kök per pass blir 1200. 9500 + 1200 = 10700
C9: Inköp mat | D9: 4029 | E9: 0 kr | F9: -10000 | J9: 50 x 200 = 10000, Schysst käk
C10: Märken | D10: 4027 | E10: 0 kr | F10: -3500 | J10: 15 x 200 = 3000
C11: P-vård | D11: 7691 | E11: 0 kr | F11: -1000 | J11: 1000 totalt
C12: Sittningsdryck | D12: 4021-4025 | E12: 0 kr | F12: -20000 | J12: ~100 x 200 = 20000
C13: SA | D13: 6800 | E13: 0 kr | F13: =-1800-500 -> -2300 | J13: 225 per timme, 17-01
C14: Teknik | D14: 5210 | E14: 0 | F14: -4000 | I14: Glömdes sist
C16: Subsubtotal | E16: =SUM(E4:E14) -> 53000 | F16: =SUM(F4:F14) -> -53000 | G16: =E16+F16 -> 0
B18: Internt
C19: Fika | D19: 7691 | E19: 0 | F19: -1350
C20: Teambuilding | D20: 7631 | E20: 0 | F20: -4500
C21: Arbetskläder | D21: 5480 | E21: 0 | F21: -4000 | H21: T- shirts, opersonliga
C23: Subsubtotal | E23: =SUM(E19:E21) -> 0 | F23: =SUM(F19:F21) -> -9850 | G23: =E23+F23 -> -9850
B25: Evenemang | I25: Katastrof borttagen
C26: Försäljning mat | D26: 3029 | E26: 4000 | F26: 0
C27: Inköp mat | D27: 4029 | E27: 0 | F27: -4000
C28: Dekoration | D28: 5411 | E28: 0 | F28: -1000 | I28: Införd av kassör
C30: Subsubtotal | E30: =SUM(E26:E28) -> 4000 | F30: =SUM(F26:F28) -> -5000 | G30: =E30+F30 -> -1000
B32: Nyårsskiftes
C33: Biljetter | D33: 3041, 3042 | E33: 8895 | F33: 0 | H33: 155Alk 110 Alkfri
C34: Sittningsdryck | D34: 3021-3025 | E34: 0 | F34: -2628 | H34: 60 sittande
C35: Mat | D35: 4029 | E35: 0 | F35: -2400 | H35: 40kr pp
C36: Kökshyra | D36: 5010 | E36: 0 | F36: -600
C37: Dekoration | D37: 5411 | E37: 0 | F37: -500
C38: Personalvård | D38: 7691 | E38: 0 | F38: -200
C39: Engångsartiklar | D39: 5463 | E39: 0 | F39: -600
C40: Märken | D40: 4027 | E40: 0 | F40: -1500
C42: Subsubtotal | E42: =SUM(E33:E40) -> 8895 | F42: =SUM(F33:F40) -> -8428 | G42: =E42+F42 -> 467
B44: Skiftes (sommar)
C45: Biljetter | D45: 3041, 3042 | E45: 8895 | F45: 0 | H45: 155Alk 110 Alkfri
C46: Sittningsdryck | D46: 3021-3025 | E46: 0 | F46: -2628 | H46: 60 sittande
C47: Mat | D47: 4029 | E47: 0 | F47: -3570 | H47: 40kr pp
C48: Kökshyra | D48: 5010 | E48: 0 | F48: 0
...

Sheet 8 - dJulkalendern
A1: Resultatställe | B1: Sekundärtresultatställe | C1: Budgetpost | D1: Konto | E1: Intäkter | F1: Utgifter | G1: Balans | H1: Kommentarer
A2: dJulkalendern
A3: Nämnd | B3: Allmänt
C4: Spons | E4: 20000 | F4: 0
C5: Priser | E5: 0 | F5: -14000
C6: dJulmärken | E6: 0 | F6: -800
C7: dHöstmärken | E7: 0 | F7: -3500
C9: Subsubtotal | E9: =SUM(E3:E8) -> 20000 | F9: =SUM(F3:F8) -> -18300 | G9: =SUM(E9:F9) -> 1700
B11: Internt
C12: Teambuilding | E12: 0 | F12: -5500
C13: Fika | E13: 0 | F13: -3300
C14: dAnkor | E14: 0 | F14: -1000
C15: Inköp profilkläder | E15: 0 | F15: -1740
C16: Försäljning profilkläder | E16: 870 | F16: 0
C18: Subsubtotal | E18: =SUM(E12:E16) -> 870 | F18: =SUM(F12:F16) -> -11540 | G18: =SUM(E18:F18) -> -10670
C20: Subtotal | E20: =SUMIFS(E2:E18,$C2:$C18,"Subsubtotal") -> 20870 | F20: =SUMIFS(F2:F18,$C2:$C18,"Subsubtotal") -> -29840 | G20: =SUM(E20:F20) -> -8970

Sheet 9 - DKM
A1: Resultatställe | B1: Sekundärtresultatställe | C1: Budgetpost | D1: Konto | E1: Intäkter | F1: Utgifter | G1: Balans | H1: Kommentarer
A2: DKM
A3: Nämnd | B3: Allmänt
C4: Utbildning | D4: 7610 | E4: 0 | F4: -8500
C5: Förbrukningsinventarier | D5: 5410 | E5: 0 | F5: -6000
C6: Förbrukningsmaterial | D6: 5460 | E6: 0 | F6: -2000
C7: Marknadsföring | D7: 3051-3053 | E7: 0 | F7: -1000
C8: KMR-avgift | D8: 6900 | E8: 0 | F8: -1240
C9: Tillstånd | D9: 6950 | E9: 0 | F9: -3600
C10: Representation | D10: 6072 | E10: 0 | F10: -1200
C12: Subsubtotal | E12: =SUM(E2:E9) -> 0 | F12: =SUM(F4:F11) -> -23540 | G12: =E12+F12 -> -23540
B14: Internt
C15: Teambuilding | D15: 7631 | E15: 0 | F15: -17000
C16: Fika | D16: 7691 | E16: 0 | F16: -7650
C17: Medaljer | D17: 7630 | E17: 0 | F17: -1000
C18: Profilkläder | D18: 5931 | E18: 0 | F18: -15000
C20: Subsubtotal | E20: =SUM(E15:E18) -> 0 | F20: =SUM(F15:F18) -> -40650 | G20: =E20+F20 -> -40650
B22: Verksamhet
C23: Försäljning dryck (exkl. MacAllan) | D23: 3021-3025 | E23: 550000 | F23: 0
C24: Inköp dryck | D24: 4021-4025 | E24: 0 | F24: -400000
C25: Inköp barkit | D25: 4031 | E25: 0 | F25: -8000 | H25: Vanliga pubbar & efterkör utan fippeldrinkar
C27: Subsubtotal | E27: =SUM(E23:E25) -> 550000 | F27: =SUM(F23:F25) -> -408000 | G27: =E27+F27 -> 142000
B29: Onsdagspubar
C30: Försäljning mat | D30: 3029 | E30: 60000 | F30: 0
C31: Inköp mat | D31: 4029 | E31: 0 | F31: -60000
C32: Dekoration | D32: 5411 | E32: 0 | F32: -9700
C33: Personalvård | D33: 7691 | E33: 0 | F33: -6000
C34: Förbrukningsmaterial | D34: 5460 | E34: 0 | F34: -7000
C35: DJ | D35: 6800 | E35: 0 | F35: -4000
C37: Subsubtotal | E37: =SUM(E30:E35) -> 60000 | F37: =SUM(F30:F35) -> -86700 | G37: =E37+F37 -> -26700
B39: Tentapub 1 (P1)
C40: Dekoration | D40: 5411 | E40: 0 | F40: -2000
C41: Barkit | D41: 4031 | E41: 0 | F41: -500
C42: Personalvård | D42: 7691 | E42: 0 | F42: -1000
C44: Subsubtotal | E44: =SUM(E40:E42) -> 0 | F44: =SUM(F40:F42) -> -3500 | G44: =E44+F44 -> -3500
B46: Tentapub 2 (P3)
C47: Dekoration | D47: 5411 | E47: 0 | F47: -2000
C48: Barkit | D48: 4031 | E48: 0 | F48: -500
C49: Personalvård | D49: 7691 | E49: 0 | F49: -1000
C51: Subsubtotal | E51: =SUM(E47:E49) -> 0 | F51: =SUM(F47:F49) -> -3500 | G51: =E51+F51 -> -3500
...

Sheet 11 - GUDAR
A1: Resultatställe | B1: Sekundärtresultatställe | C1: Budgetpost | D1: Konto | E1: Intäkter | F1: Utgifter | G1: Balans | H1: Kommentarer
A2: GUDAR
A3: Nämnd | B3: Allmänt
C4: Kontorsmaterial | D4: 6110 | E4: 0 | F4: -1000
C6: Subsubtotal | E6: =SUM(E4) -> 0 | F6: =SUM(F4) -> -1000 | G6: =E6+F6 -> -1000
B8: Internt
C9: Fika | D9: 7691 | E9: 0 | F9: -1983
C11: Subsubtotal | E11: =SUM(E9) -> 0 | F11: =SUM(F9) -> -1983 | G11: =E11+F11 -> -1983
B13: Historieföreläsning
C14: Inköp mat | D14: 4029 | E14: 0 | F14: -1750
C15: Dryck | D15: 4021 | E15: 0 | F15: -250
C17: Subsubtotal | E17: =SUM(E14:E15) -> 0 | F17: =SUM(F14:F15) -> -2000 | G17: =E17+F17 -> -2000
C19: Subtotal | E19: =SUMIFS(E2:E18,$C2:$C18,"Subsubtotal") -> 0 | F19: =SUMIFS(F2:F18,$C2:$C18,"Subsubtotal") -> -4983 | G19: =SUM(G2:G18) -> -4983

Sheet 12 - Idrottsnämnden
A1: Resultatställe | B1: Sekundärtresultatställe | C1: Budgetpost | D1: Konto | E1: Intäkter | F1: Utgifter | G1: Balans | H1: Kommentarer
A2: Idrottsnämnden
A3: Nämnd | B3: Allmänt
C4: THS Friskvårdsbidrag | D4: 3989 | E4: 30000 | F4: 0
C5: Eventfika | D5: 4045 | E5: 0 | F5: -5000
C6: Lokalhyra & Entréavgifter | D6: 5010 | E6: 0 | F6: -20000
C7: Externt arrangerade arrangemang | D7: 4620 | E7: 0 | F7: -50000 | H7: Kajak 15k, 20k Hockey, Resten valfritt
C8: Utrustning | D8: 5412 | E8: 0 | F8: -12000
C10: Subsubtotal | E10: =SUM(E4:E8) -> 30000 | F10: =SUM(F4:F8) -> -87000 | G10: =E10+F10 -> -57000
C12: Subtotal | E12: =SUMIFS(E2:E11,$C2:$C11,"Subsubtotal") -> 30000 | F12: =SUMIFS(F2:F11,$C2:$C11,"Subsubtotal") -> -87000 | G12: =SUM(G2:G11) -> -57000

Sheet 13 - IOR
A1: Resultatställe | B1: Sekundärtresultatställe | C1: Budgetpost | D1: Konto | E1: Intäkter | F1: Utgifter | G1: Balans | H1: Kommentarer
A2: Informationsorganet
A3: Nämnd | B3: Verksamhet
C4: Inköp teknik | D4: 4037 | E4: 0 | F4: -3000
C5: Discord | D5: 5420 | E5: 0 | F5: -3000
C6: Webbkostnad | D6: 6541 | E6: 0 | F6: -50000
C7: Kameratillbehör | D7: 4037 | E7: 0 | F7: -4000
I8: Sänkt 1000 pga bak till andra event tas på deras budget
C9: Subsubtotal | E9: =SUM(E2:E6) -> 0 | F9: =SUM(F2:F8) -> -60000 | G9: =E9+F9 -> -60000
B11: Internt
C12: Teambuilding | D12: 7631 | E12: 0 | F12: -5000
C13: Fika | D13: 7691 | E13: 0 | F13: -4500
C15: Subsubtotal | E15: =E12 -> 0 | F15: =SUM(F12:F13) -> -9500 | G15: =E15+F15 -> -9500
C17: Subtotal | E17: =SUMIFS(E2:E16,$C2:$C16,"Subsubtotal") -> 0 | F17: =SUMIFS(F2:F16,$C2:$C16,"Subsubtotal") -> -69500 | G17: =SUM(G2:G16) -> -69500

Sheet 14 - IN
A1: Resultatställe | B1: Sekundärtresultatställe | C1: Budgetpost | D1: Konto | E1: Intäkter | F1: Utgifter | G1: Balans | H1: Kommentarer
A2: Internationella nämnden
A3: Nämnd | B3: Event
C4: Inköp märken | D4: 4027 | E4: 0 | F4: -1500
C5: Eventfika | D5: 4045 | E5: 0 | F5: -8000
C6: Dekoration | D6: 5411 | E6: 0 | F6: 0
C7: Lokalhyra | D7: 5010 | E7: 0 | F7: -2000
C8: Externt arrangerade arrangemang | D8: 4620 | E8: 0 | F8: -2500
C9: Övriga prylar | D9: 4030 | E9: 0 | F9: -2500
C11: Subsubtotal | E11: =SUM(E4:E9) -> 0 | F11: =SUM(F4:F9) -> -16500 | G11: =E11+F11 -> -16500
B13: Allmänt
C14: Representation | D14: 6072 | E14: 0 | F14: -1000
C16: Subsubtotal | E16: =E14 -> 0 | F16: =F14 -> -1000 | G16: =E16+F16 -> -1000
B18: Internt
C19: Fika | D19: 7691 | E19: 0 | F19: -4200
C20: Inköp profilkläder | D20: 4044 | E20: 0 | F20: -10000
C21: Försäljning profilkläder | D21: 3044 | E21: 5000 | F21: 0
C22: Teambuilding | D22: 7631 | E22: 0 | F22: -7000
C24: Subsubtotal | E24: =SUM(E19:E22) -> 5000 | F24: =SUM(F19:F22) -> -21200 | G24: =E24+F24 -> -16200
B26: Mottagningssittning höst
C27: Biljetter | D27: 3041, 3042 | E27: 8490 | F27: 0
C28: Sittningsdryck | D28: 3021-3025 | E28: 0 | F28: -2376
C29: Mat | D29: 4029 | E29: 0 | F29: -2400
C30: Kökshyra | D30: 5010 | E30: 0 | F30: -600
C31: Dekoration | D31: 5411 | E31: 0 | F31: -500
C32: Personalvård | D32: 7691 | E32: 0 | F32: -200
C33: Engångsartiklar | D33: 5463 | E33: 0 | F33: -600
C34: Märken | D34: 4027 | E34: 0 | F34: -1500
C36: Subsubtotal | E36: =SUM(E27:E34) -> 8490 | F36: =SUM(F27:F34) -> -8176 | G36: =E36+F36 -> 314
B38: Mottagningssittning vår
C39: Biljetter | D39: 3041, 3042 | E39: 8490 | F39: 0
C40: Sittningsdryck | D40: 3021-3025 | E40: 0 | F40: -2376
C41: Mat | D41: 4029 | E41: 0 | F41: -3000
C42: Dekoration | D42: 5411 | E42: 0 | F42: -500
C43: Personalvård | D43: 7691 | E43: 0 | F43: -200
C44: Engångsartiklar | D44: 5463 | E44: 0 | F44: -600
C45: Märken | D45: 4027 | E45: 0 | F45: -1500
C47: Subsubtotal | E47: =SUM(E39:E45) -> 8490 | F47: =SUM(F39:F45) -> -8176 | G47: =E47+F47 -> 314
B49: Nationella sittningen (1)
C50: Biljetter | D50: 3041, 3042 | E50: 8490 | F50: 0
...

Sheet 15 - JN
A1: Resultatställe | B1: Sekundärtresultatställe | C1: Budgetpost | D1: Konto | E1: Intäkter | F1: Utgifter | G1: Balans | H1: Kommentarer
A2: Jämlikhetsnämnden
A3: Nämnd | B3: Allmänt
C4: Eventfika | D4: 4045 | E4: 0 | F4: -2000 | I4: Event splittad
C5: Dekoration & Pyssel | D5: 5411 | E5: 0 | F5: -2000
C7: Subsubtotal | E7: =SUM(E4:E5) -> 0 | F7: =SUM(F4:F5) -> -4000 | G7: =E7+F7 -> -4000
B9: Lunchföreläsningar
C10: Inköp mat | D10: 4029 | E10: 0 | F10: -8000
C12: Subsubtotal | E12: =E10 -> 0 | F12: =F10 -> -8000 | G12: =E12+F12 -> -8000
B14: Internt
C15: Teambuilding | D15: 7631 | E15: 0 | F15: -750
C16: Fika | D16: 7691 | E16: 0 | F16: -450
C18: Subsubtotal | E18: =SUM(E15:E16) -> 0 | F18: =SUM(F15:F16) -> -1200 | G18: =E18+F18 -> -1200
C20: Subtotal | E20: =SUMIFS(E2:E19,$C2:$C19,"Subsubtotal") -> 0 | F20: =SUMIFS(F2:F19,$C2:$C19,"Subsubtotal") -> -13200 | G20: =SUM(G2:G19) -> -13200

Sheet 16 - Kommunikationsgruppen
A1: Resultatställe | B1: Sekundärtresultatställe | C1: Budgetpost | D1: Konto | E1: Intäkter | F1: Utgifter | G1: Balans | H1: Kommentarer
A2: Kommunikationsgruppen
A3: Nämnd
B4: Internt
C5: Teambuilding | D5: 7631 | E5: 0 | F5: -1000
C6: Fika | D6: 7691 | E6: 0 | F6: -600
C8: Subsubtotal | E8: =SUM(E5:E6) -> 0 | F8: =SUM(F5:F6) -> -1600 | G8: =E8+F8 -> -1600
C10: Subtotal | E10: =SUMIFS(E2:E9,$C2:$C9,"Subsubtotal") -> 0 | F10: =SUMIFS(F2:F9,$C2:$C9,"Subsubtotal") -> -1600 | G10: =SUM(G2:G9) -> -1600

Sheet 17 - MKM
A1: Resultatställe | B1: Sekundärtresultatställe | C1: Budgetpost | D1: Konto | E1: Intäkter | F1: Utgifter | G1: Balans | H1: Kommentarer
A2: MKM
A3: Nämnd | B3: Verksamhet
C4: Inköp dryck | D4: 4021-4025 | E4: 0 | F4: -250000 | H4: Alkohol & alkoholfritt | I4: Justerad, bokföring 2023 var 250k
C5: Försäljning dryck | D5: 3021-3025 | E5: 400000 | F5: 0 | H5: Alkohol & alkoholfritt | I5: Justerad efter bokföring 2023, var ish 400k
C6: Inköp märken | D6: 4027 | E6: 0 | F6: -20000 | H6: Märken som säljs | I6: Justerad efter bokföring 2023
C7: Försäljning märken | D7: 3027 | E7: 20000 | F7: 0 | H7: Märken som säljs | I7: Justerad efter bokföring 2023
C8: Inköp drinkingredienser | D8: 4031 | E8: 0 | F8: -7500 | H8: Både pubbar och efterkör | I8: Namnbyte tydlighet
C9: Inköp mat pub | D9: 4029 | E9: 0 | F9: -5000 | H9: Endast pubbar
C10: Försäljning mat pub | D10: 3029 | E10: 5000 | F10: 0
C11: Dekor pub | D11: 5411 | E11: 0 | F11: -5000
C12: Teknik | D12: 4037, 5210 | E12: 0 | F12: -1000 | I12: Justerad efter bokföring 2023
C13: Underhållning | D13: 6800 | E13: 0 | F13: -3000 | H13: DJ och annat skoj för pubbar som inte är dekoration
C14: Fraktkostnader | D14: 5710, 5410 | E14: 0 | F14: 0 | H14: Frakt, lådor, pantbackar
C16: Subsubtotal | E16: =SUM(E4:E13) -> 425000 | F16: =SUM(F4:F13) -> -291500 | G16: =E16+F16 -> 133500
B18: Festmästeriet
C19: Biljetter | D19: 3041, 3042 | E19: 16750 | F19: 0
C20: Inköp mat | D20: 4029 | E20: 0 | F20: -5000
C21: Sittningsdryck | D21: 4021-4025 | E21: 0 | F21: -7500
C22: Dekoration | D22: 5411 | E22: 0 | F22: -1500
C23: Sittningsmärken | D23: 4027 | E23: 0 | F23: -1750
C24: Engångsartiklar | D24: 5463 | E24: 0 | F24: -1000
C26: Subsubtotal | E26: =SUM(E19:E24) -> 16750 | F26: =SUM(F19:F24) -> -16750 | G26: =E26+F26 -> 0
B28: Mottagningen
C29: Biljetter | D29: 3041, 3042 | E29: 37000 | F29: 0
C30: Inköp mat | D30: 4029 | E30: 0 | F30: -11000 | I30: Uppdelad
C31: Sittningsdryck | D31: 4021-4025 | E31: 0 | F31: -15000 | I31: Uppdelad
C32: Dekoration | D32: 5411 | E32: 0 | F32: -3000 | I32: Uppdelad
C33: Sittningsmärken | D33: 4027 | E33: 0 | F33: -5000 | I33: Uppdelad
C34: Engångsartiklar | D34: 5463 | E34: 0 | F34: -3000 | I34: Uppdelad
C36: Subsubtotal | E36: =SUM(E29:E34) -> 37000 | F36: =SUM(F29:F34) -> -37000 | G36: =E36+F36 -> 0
B38: Övrigt | I38: Namnbyte från allmänt
C39: Förbrukningsinventarier | D39: 5410 | E39: 0 | F39: -1200 | H39: T.ex. shakers, glas, öltorn
C40: Förbrukningsmaterial | D40: 5460 | E40: 0 | F40: -1200 | H40: Batterier och annat slitmaterial
C41: Zettlekostnader | D41: 6061 | E41: 0 | F41: -6200 | H41: Månads- och transaktionsavgift | I41: Bankkostnader borttaget
C42: Kortavgifter | D42: 6040 | E42: 0 | F42: -350 | H42: Ett debetkort
C43: Personalkostnad | D43: 6800 | E43: 0 | F43: -109050 | H43: Media fakturerar Data för personal på pubbar & dyl
C44: Marknadsföring | D44: 4051, 4054 | E44: 0 | F44: -1500 | H44: Facebook, tryck etc...
C45: KMR-avgift | D45: 6900 | E45: 0 | F45: 0
C47: Subsubtotal | E47: =SUM(E39:E44) -> 0 | F47: =SUM(F39:F44) -> -119500 | G47: =E47+F47 -> -119500
...

Sheet 18 - Mottagningen
A1: Resultatställe | B1: Sekundärtresultatställe | C1: Budgetpost | D1: Konto | E1: Intäkter | F1: Utgifter | G1: Balans | H1: Kommentarer
A2: Mottagningen
A3: Nämnd | B3: Champagne-X
C4: Mat | E4: 0 | F4: -1400
C5: Engångsartiklar | E5: 0 | F5: -400
C7: Subsubtotal | E7: =SUM(E4:E5) -> 0 | F7: =SUM(F4:F5) -> -1800 | G7: =E7+F7 -> -1800
B9: Chillhäng
C10: Mat | E10: 0 | F10: -2200
C12: Subsubtotal | E12: =SUM(E10) -> 0 | F12: =SUM(F10) -> -2200 | G12: =E12+F12 -> -2200
B14: Allmänt
C15: Diverse teknik | E15: 0 | F15: -5000
C16: Förbrukningsinventarier | E16: 0 | F16: -1000
C17: Förbrukningsmateriel | E17: 0 | F17: -1820
C18: Kontorsmaterial | E18: 0 | F18: -2000
C19: Lokalhyra | E19: 0 | F19: -15000
C20: Mörkläggning | E20: 0 | F20: -10000
C21: Representationsgåvor | E21: 0 | F21: -3000
C22: Örådsrestaurering | E22: 0 | F22: -500
C23: Övriga programvaror | E23: 0 | F23: -5000
C24: Sjuk & hälsovård | E24: 0 | F24: -3500
C26: Subsubtotal | E26: =SUM(E15:E24) -> 0 | F26: =SUM(F15:F24) -> -46820 | G26: =E26+F26 -> -46820
B28: Grafik
C29: Stickers | E29: 0 | F29: -1000
C30: Tryck | E30: 0 | F30: -35000
C31: Tygmärken | E31: 0 | F31: -35000
C32: Film & Framkallning | E32: 0 | F32: -3000
C34: Subsubtotal | E34: =SUM(E29:E32) -> 0 | F34: =SUM(F29:F32) -> -74000 | G34: =E34+F34 -> -74000
B36: Titel
C37: Fika | E37: 0 | F37: -4950
C38: Teambuilding | E38: 0 | F38: -5500
C39: Titeltillbehör | E39: 0 | F39: -1400
C40: Titelspex | E40: 0 | F40: -2700
C41: Möte med dFunkt | E41: 0 | F41: -500
C43: Subsubtotal | E43: =SUM(E37:E41) -> 0 | F43: =SUM(F37:F41) -> -15050 | G43: =E43+F43 -> -15050
B45: D4M pub
C46: Inköp mat | E46: 0 | F46: -5000
C47: Försäljning mat | E47: 5000 | F47: 0
C48: Barkit | E48: 0 | F48: -500
C49: Dekoration | E49: 0 | F49: -3000
C50: Engångsartiklar | E50: 0 | F50: -1000
...

Sheet 19 - NLG
A1: Resultatställe | B1: Sekundärtresultatställe | C1: Budgetpost | D1: Konto | E1: Intäkter | F1: Utgifter | G1: Balans | H1: Kommentarer
A2: Näringslivsgruppen
A3: Nämnd | B3: Allmänt
C4: Inköp marknadsföring | D4: 4051, 4054 | E4: 0 | F4: -12500
C5: Licenser | D5: 5420 | E5: 0 | F5: -16000 | H5: Adobe CC, LinkedIn Premium & Lime. Vaska Lime om D-Dagen inte kommer igång
C6: Kortavgift | D6: 6040 | E6: 0 | F6: -1000
C8: Subsubtotal | E8: =SUM(E4:E6) -> 0 | F8: =SUM(F4:F6) -> -29500 | G8: =E8+F8 -> -29500
B10: Internt
C11: Fika | D11: 7691 | E11: 0 | F11: -7200
C12: Teambuilding | D12: 7631 | E12: 0 | F12: -12000
C13: Medaljer | D13: 7630 | E13: 0 | F13: -1000
C14: Profilkläder | D14: 5931 | E14: 0 | F14: -6000
C16: Subsubtotal | E16: =SUM(E11:E14) -> 0 | F16: =SUM(F11:F14) -> -26200 | G16: =E16+F16 -> -26200
B18: Alumnevent
C19: Inköp mat | D19: 4029 | E19: 0 | F19: -3000 | H19: Det ska hållas 2 event för att få gå back 5k totalt
C20: Lokalhyra | D20: 5010 | E20: 0 | F20: -2000
C22: Subsubtotal | E22: =SUM(E19:E20) -> 0 | F22: =SUM(F19:F20) -> -5000 | G22: =E22+F22 -> -5000
B24: Annonsering
C25: Försäljning marknadsföring | D25: 3053 | E25: 90000 | F25: 0 | I25: Budgeterat för 15
C26: Inköp marknadsföring | D26: 4054 | E26: 0 | F26: -7500 | H26: Boost för företagsinlägg
C28: Subsubtotal | E28: =SUM(E25:E26) -> 90000 | F28: =SUM(F25:F26) -> -7500 | G28: =E28+F28 -> 82500
B30: Övrigt event
C31: Försäljning marknadsföring | D31: 3052 | E31: 90000 | F31: 0 | H31: FöretagsAW etc...
C33: Subsubtotal | E33: =E31 -> 90000 | F33: =F31 -> 0 | G33: =E33+F33 -> 90000
B35: Företagspub | I35: Uppdaterad prissänkning
C36: Baspaket | D36: 3052 | E36: =34500*3 -> 103500 | F36: 0
C37: Barbongar | D37: 2891*, 3693 | E37: =7500*3 -> 22500 | F37: 0
C38: Dryck barbongar | D38: 2891* | E38: 0 | F38: -18750
C39: Tryckkostnader | D39: 6150 | E39: 0 | F39: -2500
C40: Inköp mat | D40: 4029 | E40: 0 | F40: -39000
C42: Subsubtotal | E42: =SUM(E36:E40) -> 126000 | F42: =SUM(F36:F40) -> -60250 | G42: =E42+F42 -> 65750
B44: Lunchföreläsningar | I44: Uppdaterad prissänkning
C45: Baspaket | D45: 3052 | E45: 222000 | F45: 0
C46: Lokalhyra | D46: 5010 | E46: 0 | F46: -6000
C47: Inköp mat | D47: 4029 | E47: 0 | F47: -90000
C49: Subsubtotal | E49: =SUM(E45:E47) -> 222000 | F49: =SUM(F45:F47) -> -96000 | G49: =E49+F49 -> 126000
C51: Subtotal | E51: =SUMIFS(E2:E50,$C2:$C50,"Subsubtotal") -> 528000 | F51: =SUMIFS(F2:F50,$C2:$C50,"Subsubtotal") -> -224450 | G51: =SUM(G2:G50) -> 303550

Sheet 20 - Prylmångleriet
A1: Resultatställe | B1: Sekundärtresultatställe | C1: Budgetpost | D1: Konto | E1: Intäkter | F1: Utgifter | G1: Balans | H1: Kommentarer
A2: Prylmångleriet
A3: Nämnd | B3: Allmänt
C4: Försäljning Overaller | D4: 3028 | E4: 200000 | F4: 0
C5: Försäljning Prylis | D5: 3027 | E5: 70000 | F5: 0
C6: Försäljning kläder | D6: 3044 | E6: 70000 | F6: 0
C7: Inköp kläder | D7: 4044 | E7: 0 | F7: -70000
C8: Inköp Overaller | D8: 4028 | E8: 0 | F8: -200000
C9: Inköp Prylis | D9: 4027 | E9: 0 | F9: -70000
C10: Fraktavgifter | D10: 5710 | E10: 0 | F10: -5000
C11: Spons för overaller | D11: 3054 | E11: 21000 | F11: 0 | I11: Räknar konservativt
C12: Eventfika | D12: 4045 | E12: 0 | F12: -3000
C14: Subsubtotal | E14: =SUM(E4:E12) -> 361000 | F14: =SUM(F4:F12) -> -348000 | G14: =E14+F14 -> 13000
B16: Internt
C17: Teambuilding | D17: 7631 | E17: 0 | F17: -2000
C18: Fika | D18: 7691 | E18: 0 | F18: -1200
C20: Subsubtotal | E20: =SUM(E17:E18) -> 0 | F20: =SUM(F17:F18) -> -3200 | G20: =E20+F20 -> -3200
C22: Subtotal | E22: =SUMIFS(E2:E21,$C2:$C21,"Subsubtotal") -> 361000 | F22: =SUMIFS(F2:F21,$C2:$C21,"Subsubtotal") -> -351200 | G22: =SUM(G2:G21) -> 9800

Sheet 21 - QN
A1: Resultatställe | B1: Sekundärtresultatställe | C1: Budgetpost | D1: Konto | E1: Intäkter | F1: Utgifter | G1: Balans | H1: Kommentarer
A2: Qulturnämnden
A3: Nämnd | B3: Allmänt
C4: Eventfika | D4: 4045 | E4: 0 | F4: -10000
C5: Inköp av Qultur | D5: 4030 | E5: 0 | F5: -6000
C6: Pyssel | D6: 5411 | E6: 0 | F6: -3000
C8: Subsubtotal | E8: =SUM(E4:E5) -> 0 | F8: =SUM(F4:F7) -> -19000 | G8: =E8+F8 -> -19000
C10: Subtotal | E10: =SUMIFS(E2:E9,$C2:$C9,"Subsubtotal") -> 0 | F10: =SUMIFS(F2:F9,$C2:$C9,"Subsubtotal") -> -19000 | G10: =SUM(G2:G9) -> -19000

Sheet 22 - Redaqtionen
A1: Resultatställe | B1: Sekundärtresultatställe | C1: Budgetpost | D1: Konto | E1: Intäkter | F1: Utgifter | G1: Balans | H1: Kommentarer
A2: Redaqtionen
A3: Nämnd | B3: Allmänt
C4: Försäljning tidningar | D4: 3030 | E4: 5000 | F4: 0
C5: Tryckkostnad | D5: 6150 | E5: 0 | F5: -14000
C6: Frakt till andra lärosäten | D6: 6250 | E6: 0 | F6: -1000
C8: Subsubtotal | E8: =SUM(E2:E6) -> 5000 | F8: =SUM(F2:F6) -> -15000 | G8: =E8+F8 -> -10000
B10: Internt
C11: Teambuilding | D11: 7631 | E11: 0 | F11: -3750
C12: Fika | D12: 7691 | E12: 0 | F12: -2250
C13: Försäljning profilkläder | D13: 3044 | E13: 1500 | F13: 0
C14: Inköp profilkläder | D14: 4044 | E14: 0 | F14: -3000
C16: Subsubtotal | E16: =SUM(E11:E14) -> 1500 | F16: =SUM(F11:F14) -> -9000 | G16: =E16+F16 -> -7500
C18: Subtotal | E18: =SUMIFS(E2:E17,$C2:$C17,"Subsubtotal") -> 6500 | F18: =SUMIFS(F2:F17,$C2:$C17,"Subsubtotal") -> -24000 | G18: =SUM(G2:G17) -> -17500

Sheet 24 - SLG
A1: Resultatställe | B1: Sekundärtresultatställe | C1: Budgetpost | D1: Konto | E1: Intäkter | F1: Utgifter | G1: Balans | H1: Kommentarer
A2: Sektionslokalsgruppen
A3: Nämnd | B3: Allmänt
C4: Försäljning läskkyl | D4: 3026 | E4: 30000 | F4: 0
C5: Inköp läskkyl | D5: 4026 | E5: 0 | F5: -25000
C6: METAdryck | D6: 4021 | E6: 0 | F6: -11100
C7: Inköp förbrukningsmateriel | D7: 5460 | E7: 0 | F7: -25000
C8: Inköp förbrukningsinventarier | D8: 5410 | E8: 0 | F8: -25000
C9: Reparationer | D9: 5510 | E9: 0 | F9: -5000
C10: Städmaterial | D10: 5464 | E10: 0 | F10: -6000
C11: Medicinska artiklar | D11: 7620 | E11: 0 | F11: -2000 | H11: Inflyttad från Centralt
C12: Drifvarkaden | D12: 5410, 5510 | E12: 0 | F12: -1500
C14: Subsubtotal | E14: =SUM(E4:E10) -> 30000 | F14: =SUM(F4:F10) -> -97100 | G14: =E14+F14 -> -67100
B16: Internt
C17: Teambuilding | D17: 7631 | E17: 0 | F17: -15000
C18: Fika | D18: 7691 | E18: 0 | F18: -9000
C19: Försäljning profilkläder | D19: 3044 | E19: 7500 | F19: 0
C20: Inköp profilkläder | D20: 4044 | E20: 0 | F20: -15000
C21: Medaljer | D21: 7630 | E21: 0 | F21: -2000
C23: Subsubtotal | E23: =SUM(E17:E21) -> 7500 | F23: =SUM(F17:F21) -> -41000 | G23: =E23+F23 -> -33500
B25: Bastuevent
C26: Hyra | D26: 5010 | E26: 0 | F26: -2400
C27: Fika | D27: 7691 | E27: 0 | F27: -2000
C29: Subsubtotal | E29: =SUM(E26:E27) -> 0 | F29: =SUM(F26:F27) -> -4400 | G29: =E29+F29 -> -4400
B31: Tappar
C32: Märken | D32: 4027 | E32: 0 | F32: -3000
C34: Subsubtotal | E34: =SUM(E32) -> 0 | F34: =SUM(F32) -> -3000 | G34: =E34+F34 -> -3000
B36: Ljud och Ljus
C37: Inköp teknik | D37: 4037 | E37: 0 | F37: -20000
C39: Subsubtotal | E39: =SUM(E37) -> 0 | F39: =SUM(F37) -> -20000 | G39: =E39+F39 -> -20000
B41: Måndagsstädsfest
C42: Städsubventionering | D42: 3041, 3042 | E42: 0 | F42: -5000
C43: Biljetter | D43: 3041, 3042 | E43: 11160 | F43: 0 | H43: 195 Alk, 150 Alkfri, 65 Städare alk
C44: Sittningsdryck | D44: 4021-4025 | E44: 0 | F44: -2544 | H44: 60 pers, 20% alkfri
C45: Mat | D45: 4029 | E45: 0 | F45: -4800 | H45: 80kr pp, najs käk
C46: Kökshyra | D46: 5010 | E46: 0 | F46: 0
C47: Dekoration | D47: 5411 | E47: 0 | F47: -1100
C48: Personalvård | D48: 7691 | E48: 0 | F48: -200
C49: Märken | D49: 4027 | E49: 0 | F49: -1500
C51: Subsubtotal | E51: =SUM(E42:E49) -> 11160 | F51: =SUM(F42:F49) -> -15144 | G51: =E51+F51 -> -3984
...

Sheet 25 - Studienämnden
A1: Resultatställe | B1: Sekundärtresultatställe | C1: Budgetpost | D1: Konto | E1: Intäkter | F1: Utgifter | G1: Balans | H1: Kommentarer
A2: Studienämnden
A3: Nämnd | B3: Allmänt
C4: Evenemang | E4: 0 | F4: -7000
C5: Lunchföreläsningar | E5: 0 | F5: -5300
C7: Subsubtotal | E7: =SUM(E4:E6) -> 0 | F7: =SUM(F4:F6) -> -12300 | G7: =SUM(E7:F7) -> -12300
B9: Internt
C10: Biljettintäkter | E10: 2000 | F10: 0
C11: Fika | E11: 0 | F11: -6300
C12: Försäljning profilkläder | E12: 6400 | F12: 0
C13: Inköp profilkläder | E13: 0 | F13: -12800
C14: Kursnämndsmiddag | E14: 0 | F14: -6300
C15: Teambuilding | E15: 0 | F15: -10500
C17: Subsubtotal | E17: =SUM(E9:E16) -> 8400 | F17: =SUM(F9:F16) -> -35900 | G17: =SUM(E17:F17) -> -27500
C19: Subtotal | E19: =SUMIFS(E4:E18,$C4:$C18,"Subsubtotal") -> 8400 | F19: =SUMIFS(F4:F18,$C4:$C18,"Subsubtotal") -> -48200 | G19: =SUM(E19:F19) -> -39800

Sheet 26 - Dive
A1: Resultatställe | B1: Sekundärtresultatställe | C1: Budgetpost | D1: Konto | E1: Intäkter | F1: Utgifter | G1: Balans | H1: Kommentarer
A2: Dive
A3: Nämnd | B3: Allmänt
C4: Fika extern | D4: 4045 | E4: 0 | F4: -2000
C5: Tryck och marknadsföring | D5: 4051-4054 | E5: 0 | F5: -7000
C6: Transport | D6: 5690 | E6: 0 | F6: -1000
C7: Inköp besöksmaterial | D7: 4030 | E7: 0 | F7: -2500
C8: Inköp Mat till event | D8: 4029 | E8: 0 | F8: -10000
C9: Spons till event | D9: 3988 | E9: 6000 | F9: 0
C11: Subsubtotal | E11: =SUM(E2:E10) -> 6000 | F11: =SUM(F2:F10) -> -22500 | G11: =E11+F11 -> -16500
B13: Internt
C14: Fika | D14: 7691 | E14: 0 | F14: -4200
C15: Teambuilding | D15: 7631 | E15: 0 | F15: -3500
C16: Retorikutbildning | D16: 5460 | E16: 0 | F16: -1000
C18: Subsubtotal | E18: =SUM(E15:E16) -> 0 | F18: =SUM(F15:F16) -> -4500 | G18: =E18+F18 -> -4500
C20: Subtotal | E20: =SUMIFS(E2:E19,$C2:$C19,"Subsubtotal") -> 6000 | F20: =SUMIFS(F2:F19,$C2:$C19,"Subsubtotal") -> -27000 | G20: =SUM(G2:G19) -> -21000

Sheet Datas DansRevolution
A1: Resultatställe | B1: Sekundärtresultatställe | C1: Budgetpost | D1: Konto | E1: Intäkter | F1: Utgifter | G1: Balans | H1: Kommentarer
A2: Datas DansRevolution
A3: Projekt | B3: Internt
C4: Allmänt | D4: 4045 | E4: 0 | F4: -750
C6: Subsubtotal | E6: =SUM(E3:E5) -> 0 | F6: =SUM(F3:F5) -> -750 | G6: =SUM(E6:F6) -> -750
C8: Subtotal | E8: =SUMIFS(E2:E7,$C2:$C7,"Subsubtotal") -> 0 | F8: =SUMIFS(F2:F7,$C2:$C7,"Subsubtotal") -> -750 | G8: =SUM(E8:F8) -> -750

Sheet 103 - Studs 2025
A1: Resultatställe | B1: Sekundärtresultatställe | C1: Budgetpost | D1: Konto | E1: Intäkter | F1: Utgifter | G1: Balans | H1: Kommentarer
A2: Studs 2025
A3: Projekt | B3: Företagsevent | H3: Antal studsare: 25
C4: Företagsevent | D4: 3052 | E4: 756500 | F4: 0
C5: Företagspresenter | D5: 6072 | E5: 0 | F5: -3360
C6: Startup-pub | D6: 3052 | E6: 50800 | F6: 0
C7: Inköp mat | E7: 0 | F7: -5400
C9: Subsubtotal | E9: =SUM(E4:E7) -> 807300 | F9: =SUM(F4:F7) -> -8760 | G9: =SUM(E9:F9) -> 798540
B11: Allmänt
C12: Licenser | E12: 0 | F12: -12250 | H12: Adobe CC
C13: Tryck | E13: 0 | F13: -6000
C14: Kontokortsavgifter | E14: 0 | F14: -500
C15: Webbavgifter | D15: 6541 | E15: 0 | F15: -3200
C16: Utskick av rapport | E16: 0 | F16: -1500
C17: PR | D17: 4053 | E17: 0 | F17: -20000
C19: Subsubtotal | E19: =SUM(E12:E17) -> 0 | F19: =SUM(F12:F17) -> -43450 | G19: =SUM(E19:F19) -> -43450
B21: Resa
C22: Resekostnader | D22: 5800 | E22: 0 | F22: -315000
C23: Boende | D23: 5830 | E23: 0 | F23: -162000
C24: Studieaktiviteter | D24: 5890 | E24: 0 | F24: -80000
C25: Mat | D25: 7692 | E25: 0 | F25: -126000 | H25: Ingen alk!
C27: Subsubtotal | E27: =SUM(E22:E25) -> 0 | F27: =SUM(F22:F25) -> -683000 | G27: =SUM(E27:F27) -> -683000
B29: Överlämning
C30: Dekoration | E30: 0 | F30: -850
C31: Inköp mat | E31: 0 | F31: -7000
C32: Engångsartiklar | E32: 0 | F32: -300
C34: Subsubtotal | E34: =SUM(E30:E32) -> 0 | F34: =SUM(F30:F32) -> -8150 | G34: =SUM(E34:F34) -> -8150
B36: Informationsträffar
C37: Inköp mat | E37: 0 | F37: -12000
C39: Subsubtotal | E39: =SUM(E37) -> 0 | F39: =SUM(F37) -> -12000 | G39: =SUM(E39:F39) -> -12000
B41: Internt
C42: Fika | D42: 7691 | E42: 0 | F42: -6000
C43: Profilmaterial | E43: 0 | F43: -18000
C44: Profilaccessoarer | E44: 0 | F44: -3600
C45: Teambuilding | D45: 7631 | E45: 0 | F45: -18000
C47: Subsubtotal | E47: =SUM(E42:E45) -> 0 | F47: =SUM(F42:F45) -> -45600 | G47: =SUM(E47:F47) -> -45600
C49: Subtotal | E49: =SUMIFS(E4:E48, $C4:$C48, "Subsubtotal") -> 807300 | F49: =SUMIFS(F4:F48, $C4:$C48, "Subsubtotal") -> -800960 | G49: =SUM(E49:F49) -> 6340

Sheet 109 - METAspexet 2026
A1: Resultatställe | B1: Sekundärtresultatställe | C1: Budgetpost | D1: Konto | E1: Intäkter | F1: Utgifter | G1: Balans | H1: Kommentarer | I1: Changelog inför 2026
A2: METAspexet 2026
A3: Projekt | B3: Utbildningshelg
C4: Lokalhyra | D4: 5010 | E4: 0 | F4: -3600
C5: Mat och dryck utbildning | D5: 7692 | E5: 0 | F5: -1500
C6: Mat och dryck teambuilding | D6: 7692 | E6: 0 | F6: -1500
C7: Fika | D7: 7691 | E7: 0 | F7: -500
C9: Subsubtotal | E9: =SUM(E4:E7) -> 0 | F9: =SUM(F4:F7) -> -7100 | G9: =SUM(E9:F9) -> -7100
B11: Internt
C12: Fika för föreställningar | D12: 7691 | E12: 0 | F12: -3000 | I12: Höjt från -2 000kr
C13: Fika för grupper | D13: 7691 | E13: 0 | F13: -20200 | I13: Höjt från -16 550 kr
C14: Fika för musiknummerrep | D14: 7691 | E14: 0 | F14: -2000 | I14: Höjt från -1 000 kr
C15: Fika för samrep | D15: 7691 | E15: 0 | F15: -3600
C16: Medaljer | D16: 7630 | E16: 0 | F16: -2000
C17: Rosor | D17: 7630 | E17: 0 | F17: -1000
C18: Teambuilding | D18: 7631 | E18: 0 | F18: -23750
C20: Subsubtotal | E20: =SUM(E12:E18) -> 0 | F20: =SUM(F12:F18) -> -55550 | G20: =SUM(E20:F20) -> -55550
B22: Allmänt
C23: ABF-bidrag | D23: 3989 | E23: 40000 | F23: 0 | I23: Lokalhyror avdragna från sponsen
C24: Sektionen för Medietekniks bidrag | D24: 3989 | E24: 25000 | F24: 0
C25: Dekishyra | D25: 5010 | E25: 0 | F25: -2000
C26: PR-Banderoll upphängning | D26: 5930 | E26: 0 | F26: -2000
C27: Mjuk- och hårdvarukostnader | D27: 5420 | E27: 0 | F27: -3000
C29: Subsubtotal | E29: =SUM(E23:E27) -> 65000 | F29: =SUM(F23:F27) -> -7000 | G29: =SUM(E29:F29) -> 58000
B31: Bandet
C32: Replokalhyra | D32: 5010 | E32: 0 | F32: -9000 | I32: Tillagd
C34: Subsubtotal | E34: =SUM(E32) -> 0 | F34: =SUM(F32) -> -9000 | G34: =SUM(E34:F34) -> -9000
B35: Bügg
C36: Förbrukningsinventarier | D36: 5410 | E36: 0 | F36: -2000
C37: Förbrukningsmaterial | D37: 5460 | E37: 0 | F37: -2000 | I37: Sänkt från 3k
C38: Byggmaterial | D38: 5462 | E38: 0 | F38: -12000 | I38: Sänkt från 15k
C39: Skyddsutrustning | D39: 5480 | E39: 0 | F39: -1000
C40: Rekvisita | D40: 4036 | E40: 0 | F40: -5000
C42: Subsubtotal | E42: =SUM(E36:E40) -> 0 | F42: =SUM(F36:F40) -> -22000 | G42: =SUM(E42:F42) -> -22000
B44: Foto & Film
C45: Fotoförstoring | D45: 6150 | E45: 0 | F45: -600
C46: Förbrukningsinventarier | D46: 5410 | E46: 0 | F46: -400 | I46: Sänkt från 750
C48: Subsubtotal | E48: =SUM(E45:E46) -> 0 | F48: =SUM(F45:F46) -> -1000 | G48: =SUM(E48:F48) -> -1000
B50: Grafique
C51: Försäljning, Hoodies | D51: 3044 | E51: =ABS(F57) -> 22000 | F51: 0 | G51: =E51+F51 -> 22000 | H51: Osäker på siffror | I51: Höjd från 16 500 kr
...

Sheet 111 - dÅre 2026
A1: Resultatställe | B1: Sekundärtresultatställe | C1: Budgetpost | D1: Konto | E1: Intäkter | F1: Utgifter | G1: Balans | H1: Kommentarer | I1: Changelog inför 2026
A2: dÅre 2026
A3: Projekt | B3: Internt
C4: Teambuilding | D4: 7631 | E4: 0 | F4: -2250
C5: Fika | D5: 7691 | E5: 0 | F5: -960 | I5: Var -1800 kr
C6: Försäljning profilkläder | D6: 3044 | E6: =ABS(F7/2) -> 2100 | F6: 0 | H6: Bör inte subventioneras för dÅre 2027
C7: Inköp profilkläder | D7: 4044 | E7: 0 | F7: -4200 | I7: Omgjord från bara inköp till försäljning och inköp med samma resultat, för tydligheten och enhetlighetens skull
C8: Tackgåva | D8: 7630 | E8: 0 | F8: -700
C10: Subsubtotal | E10: =SUM(E4:E8) -> 2100 | F10: =SUM(F4:F8) -> -8110 | G10: =SUM(E10:F10) -> -6010 | I10: Oförändrad
B12: Resan
C13: Biljetter, resenärer | D13: 3041 | E13: 576690 | F13: 0 | H13: 103*4500+33*3430 | I13: Ökad från 532 000 kr
C14: Biljetter, dÅrestaben | D14: 3041 | E14: 32790 | F14: 0 | H14: 5*4500+3*3430 | I14: Ökad från 31 200 kr
C15: Boende, liftkort | D15: 5830, 5890 | E15: 0 | F15: -474480 | H15: 3295*144 | I15: Ökad från - 421 760 kr
C16: Transport | D16: 5800 | E16: 0 | F16: -115560 | H16: 1070*108 | I16: Ökad från - 114 000 kr
C17: Subventionering | D17: 3041 | E17: 0 | F17: -115200 | H17: -800*144 | I17: Ökad från - 102 400 kr
C18: Stjärtlappar och priser | D18: 5410, 7630 | E18: 0 | F18: -432 | I18: Ökad från - 300 kr
C19: Kläder till resande | D19: 4044 | E19: 0 | F19: -14400 | I19: Minskad från -17 000 kr
C20: Tygmärken | D20: 4027 | E20: 0 | F20: -4320 | I20: Oförändrad
C22: Subsubtotal | E22: =SUM(E13:E20) -> 609480 | F22: =SUM(F13:F20) -> -724392 | G22: =SUM(E22:F22) -> -114912 | H22: Ökning pga ökade antal platser | I22: Ökad från - 102 260 kr
C24: Subtotal | E24: =SUMIFS(E4:E22,$C4:$C22,"Subsubtotal") -> 611580 | F24: =SUMIFS(F4:F22,$C4:$C22,"Subsubtotal") -> -732502 | G24: =SUM(E24+F24) -> -120922

Sheet METAcraft
A1: Resultatställe | B1: Sekundärtresultatställe | C1: Budgetpost | D1: Konto | E1: Intäkter | F1: Utgifter | G1: Balans | H1: Kommentarer | I1: Changlog inför 2026
A2: METAcraft
A3: Partition | B3: Allmänt
C4: Hosting | D4: 6541 | E4: 0 | F4: -8000
C5: Teambuilding | D5: 7631 | E5: 0 | F5: -1250
C7: Subsubtotal | E7: =SUM(E4:E5) -> 0 | F7: =SUM(F4:F5) -> -9250 | G7: =E7+F7 -> -9250
C9: Subtotal | E9: =SUMIFS(E2:E8,$C2:$C8,"Subsubtotal") -> 0 | F9: =SUMIFS(F2:F8,$C2:$C8,"Subsubtotal") -> -9250 | G9: =SUM(G2:G8) -> -9250

Sheet Bakverket
A1: Resultatställe | B1: Sekundärtresultatställe | C1: Budgetpost | D1: Konto | E1: Intäkter | F1: Utgifter | G1: Balans | H1: Kommentarer
A2: Bakverket
A3: Partition | B3: Allmänt
C4: Förbrukningsinventarier | D4: 4037 | E4: 0 | F4: -1000
C5: Engångsartiklar | D5: 5463 | E5: 0 | F5: -500
C6: Ätbart guld | D6: 5411 | E6: 0 | F6: -1000
C7: Ingredienser | D7: 4045 | E7: 0 | F7: -5000 | I7: Sänkt 1000 pga bak till andra event tas på deras budget
C8: Fika under bak | D8: 7691 | E8: 0 | F8: -500
C9: Lokalhyra | D9: 5010 | E9: 0 | F9: -3600
C11: Subsubtotal | E11: =SUM(E4:E9) -> 0 | F11: =SUM(F4:F9) -> -11600 | G11: =E11+F11 -> -11600
C13: Subtotal | E13: =SUMIFS(E2:E11,$C2:$C11,"Subsubtotal") -> 0 | F13: =SUMIFS(F2:F11,$C2:$C11,"Subsubtotal") -> -11600 | G13: =SUM(G2:G11) -> -11600

Sheet Scala
A1: Resultatställe | B1: Sekundärtresultatställe | C1: Budgetpost | D1: Konto | E1: Intäkter | F1: Utgifter | G1: Balans | H1: Kommentarer
A2: Scala
A3: Partition | B3: Internt
C4: Fika | D4: 7691 | E4: 0 | F4: -1500
C5: Noter | E5: 0 | F5: -150
C7: Subsubtotal | E7: =SUM(E4) -> 0 | F7: =SUM(F4:F5) -> -1650 | G7: =E7+F7 -> -1650
C9: Subtotal | E9: =SUMIFS(E2:E7,$C2:$C7,"Subsubtotal") -> 0 | F9: =SUMIFS(F2:F7,$C2:$C7,"Subsubtotal") -> -1650 | G9: =SUM(G2:G7) -> -1650

Sheet Tech-i-taka
A1: Resultatställe | B1: Sekundärtresultatställe | C1: Budgetpost | D1: Konto | E1: Intäkter | F1: Utgifter | G1: Balans | H1: Kommentarer
A2: Tech-i-taka
A3: Partition | B3: Allmänt
C4: Serieavgift | D4: 6900 | E4: 0 | F4: -14400
C5: Domaravgift | D5: 6800 | E5: 0 | F5: -2800
C6: Material | D6: 5412 | E6: 0 | F6: -3000
C7: Plantider | D7: 5010 | E7: 0 | F7: -5600
C9: Subsubtotal | E9: =SUM(E4:E7) -> 0 | F9: =SUM(F4:F7) -> -25800 | G9: =E9+F9 -> -25800
B11: Internt
C12: Inköp profilkläder | D12: 4044 | E12: 0 | F12: -6000 | I12: Råhöftad
C13: Försäljning profilkläder | D13: 3044 | E13: 3000 | F13: 0
C14: Fika | D14: 7691 | E14: 0 | F14: -2400
C17: Subsubtotal | E17: =SUM(E12:E15) -> 3000 | F17: =SUM(F12:F15) -> -8400 | G17: =E17+F17 -> -5400
C19: Subtotal | E19: =SUMIFS(E2:E18,$C2:$C18,"Subsubtotal") -> 3000 | F19: =SUMIFS(F2:F18,$C2:$C18,"Subsubtotal") -> -34200 | G19: =SUM(G2:G18) -> -31200

Sheet Vårbalen 2026
A1: Resultatställe | B1: Sekundärtresultatställe | C1: Budgetpost | D1: Konto | E1: Intäkter | F1: Utgifter | G1: Balans | H1: Kommentarer | I1: Changelog inför 2026
A2: Vårbalen 2026
A3: Projekt x | B3: Allmänt
C4: Teambuilding | D4: 7631 | E4: 0 | F4: -1750
C5: Tillstånd | D5: 6950 | E5: 0 | F5: -1131 | I5: Höjd från -1000 kr
C6: PR | D6: 4010, 6150 | E6: 0 | F6: -1500
C7: Fika | D7: 7691 | E7: 0 | F7: -840 | I7: Sänkt från -1 050 kr
C9: Subsubtotal | E9: =SUM(E4:E7) -> 0 | F9: =SUM(F4:F7) -> -5221 | G9: =SUM(E9:F9) -> -5221
B11: VårBal
C12: Biljetter | D12: 3041, 3042 | E12: 104970 | F12: 0 | H12: 115 á 550kr, 20 á 470 kr, 35 á 900 kr, 5 á 820 kr | I12: Höjd från +99 500
C13: Lokalhyra | D13: 5010 | E13: 0 | F13: -36000 | H13: Lokal 10-sent 28500, extraavgift för fler gäster 7500
C14: Personal | D14: 6800 | E14: 0 | F14: -8000 | I14: Sänkt från -13 000 kr
C15: Hyrgods | D15: 5210, 5220 | E15: 0 | F15: -8700
C16: Mat | D16: 4029 | E16: 0 | F16: -80000 | I16: Sänkt från -122 423 kr (laga egen mat)
C17: Alkfri dryck | D17: 4021 | E17: 0 | F17: -4000
C18: Alkfull dryck | D18: 4022-4025 | E18: 0 | F18: -20000
C19: Dekoration | D19: 5411 | E19: 0 | F19: -6000 | I19: Sänkt från −6077,4
C20: Märken | D20: 4027 | E20: 0 | F20: -2300
C21: Teknik | D21: 5210 | E21: 0 | F21: -10000 | I21: Döda DJ
C22: Tryck | D22: 6150 | E22: 0 | F22: -2500
C24: Subsubtotal | E24: =SUM(E12:E22) -> 104970 | F24: =SUM(F12:F22) -> -177500 | G24: =SUM(E24:F24) -> -72530
B26: Vårbalken
C27: Osqvikhyra | D27: 5010 | E27: 0 | F27: -3600
C28: Dekoration | D28: 5411 | E28: 0 | F28: -300
C29: Märken | D29: 4027 | E29: 0 | F29: -1400
C30: Mat | D30: 4029 | E30: 0 | F30: -3000
C31: Biljettförsäljning | D31: 3041 | E31: 8300 | F31: 0 | I31: Höjd från +3000 kr
C33: Subsubtotal | E33: =SUM(E27:E31) -> 8300 | F33: =SUM(F27:F31) -> -8300 | G33: =SUM(E33:F33) -> 0
B35: Efterkör
C36: Inköp dryck | D36: 4021-4025 | E36: 0 | F36: -6000
C37: Försäljning dryck | D37: 3021-3025 | E37: 8000 | F37: 0
C38: Barkit | D38: 4031 | E38: 0 | F38: -1700
C40: Subsubtotal | E40: =SUM(E37:E38) -> 8000 | F40: =SUM(F36:F38) -> -7700 | G40: =SUM(E40:F40) -> 300
C42: Subtotal | E42: =SUMIFS(E6:E41,C6:C41,"Subsubtotal") -> 121270 | F42: =SUMIFS(F6:F41,C6:C41,"Subsubtotal") -> -198721 | G42: =SUM(E42:F42) -> -77451

Sheet 201 - Centralt
A1: Resultatställe | B1: Sekundärtresultatställe | C1: Budgetpost | D1: Konto | E1: Intäkter | F1: Utgifter | G1: Balans | H1: Kommentarer
A2: Centralt
A3: Övrigt | B3: Allmänt
C4: Sektionsavgift | D4: 3061 | E4: 50000 | F4: 0
C5: EECS-bidrag | D5: 3989 | E5: =160000+26000+9000+9000 -> 204000 | F5: 0
C6: Påminnelseavgifter | D6: 6920 | E6: 0 | F6: 0
C7: Bankavgifter | D7: 6570 | E7: 0 | F7: -40000
C8: Bokföringsprogram | D8: 6541 | E8: 0 | F8: -15000
C9: Försäljningsavgifter Zettle | D9: 6061 | E9: 0 | F9: -45000
C10: Försäljningsavgifter Stripe & Confetti | D10: 6062 | E10: 0 | F10: -35000
C11: Tillsynsavgifter Myndigheter | D11: 6950 | E11: 0 | F11: -10000
C12: Förrådshyra | D12: 5010 | E12: 0 | F12: -86000 | I12: CSS + R1 + R2 (!)
C13: Avfallshanteringsavgifter | D13: 5060 | E13: 0 | F13: -30000
C14: Försäkring | D14: 6310 | E14: 0 | F14: -15000
C15: Kontorsmaterial | D15: 6110 | E15: 0 | F15: -3000
C16: Kontokortsavgifter | D16: 6040 | E16: 0 | F16: -350 | I16: SEB, 350/år
C17: Ränteintäkter | E17: 20000 | F17: 0 | I17: SEB, Räknar med 1 mille konstant
C19: Subsubtotal | E19: =SUM(E2:E18) -> 274000 | F19: =SUM(F2:F18) -> -279350 | G19: =E19+F19 -> -5350
B21: Utbildning
C22: Mat | D22: 7692 | E22: 0 | F22: -15000
C23: Fika | D23: 7691 | E23: 0 | F23: -2000
C24: Förbrukningsmaterial HLR | D24: 7610 | E24: 0 | F24: -2000
C26: Subsubtotal | E26: =SUM(E22:E24) -> 0 | F26: =SUM(F22:F24) -> -19000 | G26: =E26+F26 -> -19000
B28: Sektionsmöte (SM)
C29: Mat och dricka | D29: 4021, 4029 | E29: 0 | F29: -55000
C30: Fika | D30: 4045 | E30: 0 | F30: -1500
C31: Märken | D31: 4027 | E31: 0 | F31: -1500
C33: Subsubtotal | E33: =SUM(E29:E31) -> 0 | F33: =SUM(F29:F31) -> -58000 | G33: =E33+F33 -> -58000
C35: Subtotal | E35: =SUMIFS(E2:E34,$C2:$C34,"Subsubtotal") -> 274000 | F35: =SUMIFS(F2:F34,$C2:$C34,"Subsubtotal") -> -356350 | G35: =SUM(G2:G34) -> -82350

Sheet 202 - Beslutspengar - Engångsko
A1: Resultatställe | B1: Sekundärtresultatställe | C1: Budgetpost | D1: Konto | E1: Intäkter | F1: Utgifter | G1: Balans | H1: Kommentarer
A2: Beslutspengar - Engångskostnader
A3: Övrigt | B3: Engångskostnader
C4: Utklädnad till Talman och Vice Talman | D4: 5931 | E4: 0 | F4: -2000
C5: Inköp av stolar | E5: 0 | F5: -12000
C6: Inköp broderimaskin | E6: 0 | F6: -4500
C7: Inköp broderitillbehör | E7: 0 | F7: -2000
C8: Inköp av snickarbyxor | D8: 4044 | E8: 0 | F8: -25000
C9: Lime Go Abonnemang | E9: 0 | F9: -39150
C10: Reperation av Flippret | E10: 0 | F10: -12000
C11: Förtjänsttecken | E11: 0 | F11: -13000
C12: Ljuddämpning av META | E12: 0 | F12: -9000
C13: Material till västar | E13: 0 | F13: -13000
C14: Inköp tält | E14: 0 | F14: -5000
C15: HLR-instruktörsutbildning | E15: 0 | F15: -3500
C17: Subsubtotal | E17: =SUM(E4:E11) -> 0 | F17: =SUM(F4:F14) -> -136650 | G17: =E17+F17 -> -136650
B19: Dispfonden
C22: Subsubtotal | E22: =E20 -> 0 | F22: =F20 -> 0 | G22: =E22+F22 -> 0
C24: Subtotal | E24: =SUMIFS(E2:E23,$C2:$C23,"Subsubtotal") -> 0 | F24: =SUMIFS(F2:F23,$C2:$C23,"Subsubtotal") -> -136650 | G24: =SUM(G2:G23) -> -136650

Sheet 203 - dFunk
A1: Resultatställe | B1: Sekundärtresultatställe | C1: Budgetpost | D1: Konto | E1: Intäkter | F1: Utgifter | G1: Balans | H1: Kommentarer
A2: dFunk
A3: Övrigt | B3: Allmänt
C4: dFunkteambuilding | D4: 7631 | E4: 0 | F4: -15000 | I4: Hyvlad, reality check
C5: dFunklunch | D5: 7692 | E5: 0 | F5: -10000 | H5: 2 st luncher
C6: Julklappar dFunkt | D6: 7630 | E6: 0 | F6: -10000 | I6: Höjd
C7: dFunktavla | D7: 6150 | E7: 0 | F7: -1000 | I7: Flyttad hit från SLG
C9: Subsubtotal | E9: =SUM(E4:E7) -> 0 | F9: =SUM(F4:F7) -> -36000 | G9: =E9+F9 -> -36000
B11: Överlämning
C12: Mat dFunköverlämning | D12: 7692 | E12: 0 | F12: -6000 | I12: Reality check
C14: Subsubtotal | E14: =E12 -> 0 | F14: =F12 -> -6000 | G14: =E14+F14 -> -6000
B16: D-råd
C17: Fika | D17: 7691 | E17: 0 | F17: -6000
C19: Subsubtotal | E19: =E17 -> 0 | F19: =F17 -> -6000 | G19: =E19+F19 -> -6000
B21: Bifftes | I21: Vi ska äta på riktiga tallrikar
C22: Mat | D22: 7692 | E22: 0 | F22: -3000
C23: Dryck | D23: 7693 (7692) | E23: 0 | F23: -1000
C25: Subsubtotal | E25: 0 kr | F25: =SUM(F22) -> -3000
C27: Subtotal | E27: =SUMIFS(E2:E26,$C2:$C26,"Subsubtotal") -> 0 | F27: =SUMIFS(F2:F26,$C2:$C26,"Subsubtotal") -> -51000 | G27: =SUM(G2:G26) -> -48000

Sheet 204 - D-Rektoratet
A1: Resultatställe | B1: Sekundärtresultatställe | C1: Budgetpost | D1: Konto | E1: Intäkter | F1: Utgifter | G1: Balans | H1: Kommentarer
A2: D-Rektoratet
A3: Övrigt | B3: Allmänt
C4: Extern Representation | D4: 6072 | E4: 0 | F4: -30000 | H4: Styrelsemiddagar 10000, Representation 20000. Ej alkohol
C5: Tryckkostnader | D5: 6150 | E5: 0 | F5: -2500
C6: Porto | D6: 6250 | E6: 0 | F6: -1000
C7: Ordenstecken och Medaljer | D7: 7630 | E7: 0 | F7: -20000 | I7: Höjd pga inköp av nya medaljband samt plakett till Hedersmedlemmar
C9: Subsubtotal | E9: =SUM(E4:E7) -> 0 | F9: =SUM(F4:F7) -> -53500 | G9: =E9+F9 -> -53500
B11: Internt
C12: Inköp profilkläder | D12: 4044 | E12: 0 | F12: -9000 | I12: Uppdelad
C13: Försäljning profilkläder | D13: 3044 | E13: 4500 | F13: 0
C14: Teambuilding | D14: 7631 | E14: 0 | F14: -9000
C15: Fika | D15: 7691 | E15: 0 | F15: -5400
C17: Subsubtotal | E17: =SUM(E12:E15) -> 4500 | F17: =SUM(F12:F15) -> -23400 | G17: =E17+F17 -> -18900
B19: Möten
C20: Kanslifrukost | D20: 4045 | E20: 0 | F20: -3000
C21: D-råd fika | D21: 4045 | E21: 0 | F21: -6000
C22: DM och Motionsskrivarstuga fika | D22: 4045 | E22: 0 | F22: -3000
C24: Subsubtotal | E24: =SUM(E20:E22) -> 0 | F24: =SUM(F20:F22) -> -12000 | G24: =E24+F24 -> -12000
B26: D-Forum
C27: Anmälningsavgift | D27: 4041 | E27: 0 | F27: -10000
C28: Boende | D28: 5830 | E28: 0 | F28: -15000
C29: Resa | D29: 5800 | E29: 0 | F29: -7500
C31: Subsubtotal | E31: =SUM(E27:E29) -> 0 | F31: =SUM(F27:F29) -> -32500 | G31: =E31+F31 -> -32500
B33: D-wreckmiddag
C34: Biljetter | D34: 3041, 3042 | E34: 1600 | F34: 0 | I34: Alumnevent praxis
C35: Inköp mat | D35: 4029 | E35: 0 | F35: -2000
C36: Dekoration | D36: 5411 | E36: 0 | F36: -500
C37: Kökshyra | D37: 5010 | E37: 0 | F37: -600
C38: Sittningsdryck | D38: 4021-4025 | E38: 0 | F38: -1000
C40: Subsubtotal | E40: =SUM(E34:E38) -> 1600 | F40: =SUM(F34:F38) -> -4100 | G40: =E40+F40 -> -2500
C43: Subtotal | E43: =SUMIFS(E2:E42,$C2:$C42,"Subsubtotal") -> 6100 | F43: =SUMIFS(F2:F42,$C2:$C42,"Subsubtotal") -> -125500 | G43: =SUM(G2:G42) -> -119400

Sheet 205 - Valberedningen
A1: Resultatställe | B1: Sekundärtresultatställe | C1: Budgetpost | D1: Konto | E1: Intäkter | F1: Utgifter | G1: Balans | H1: Kommentarer
A2: Valberedningen
A3: Övrigt | B3: Allmänt
C4: Rosor (Valgåvor) | D4: 7630 | E4: 0 | F4: -2000
C6: Subsubtotal | E6: =E4 -> 0 | F6: =F4 -> -2000 | G6: =E6+F6 -> -2000
B8: Internt
C9: Teambuilding | D9: 7631 | E9: 0 | F9: -3500
